Workbook

Sheet SCENARIO_LAB
A1: ACTIVE SCENARIO | B1: Base Case
A3: Scenario | B3: Clients | C3: Rev/Client | D3: Trainers | E3: Salary | F3: Marketing
A4: Base Case | B4: 60 | C4: 12000 | D4: 3 | E4: 35000 | F4: 20000
A5: Price Increase | B5: 60 | C5: 13500 | D5: 3 | E5: 35000 | F5: 20000
A6: Growth Case | B6: 75 | C6: 12000 | D6: 4 | E6: 35000 | F6: 25000
A8: SCENARIO DRIVERS | E8: SCENARIO RESULTS
A9: Driver | B9: Scenario Value | E9: Monthly Revenue | F9: =DASHBOARD!C6 -> 720000
A10: Active Clients | B10: =_xlfn.XLOOKUP(B1, A4:A6, B4:B6) -> 60 | E10: Monthly Profit | F10: =DASHBOARD!B9 -> 540000
A11: Revenue per client | B11: =_xlfn.XLOOKUP(B1, A4:A6, C4:C6) -> 12000 | E11: Profit Margin | F11: =DASHBOARD!E9 -> 0.75
A12: Number of trainers | B12: =_xlfn.XLOOKUP(B1,A4:A6, D4:D6) -> 3 | E12: Revenue Realization | F12: =DASHBOARD!H6 -> 0.57692308
A13: Trainer Salary | B13: =_xlfn.XLOOKUP(B1,A4:A6, E4:E6) -> 35000 | E13: Capacity Pressure | F13: =DASHBOARD!F9 -> 0.76923077
A14: Marketing spend | B14: =_xlfn.XLOOKUP(B1,A4:A6, F4:F6) -> 20000
A15: Rent | B15: 100000
A16: Utilities | B16: 25000

Sheet INPUTS 
A1: STUDIO CORE DRIVERS
A3: Active clients | B3: =SCENARIO_LAB!B10 -> 60
A4: Average Price (Monthly) | B4: 12000
A5: Price per Session | B5: =B4/B6 -> 750
A6: Number of Sessions per Client (Monthly) | B6: 16
A7: Number of Trainers | B7: =SCENARIO_LAB!B12 -> 3
A8: Trainer Salary (per month) | B8: =SCENARIO_LAB!B13 -> 35000
A9: Monthly rent | B9: =SCENARIO_LAB!B15 -> 100000
A10: Monthly Marketing Spend | B10: =SCENARIO_LAB!B14 -> 20000
A11: Utilities / Miscellaneous | B11: =SCENARIO_LAB!B16 -> 25000
A13: Calculated metrices
A15: Estimated monthly revenue | B15: =B4*B3 -> 720000
A16: Total Fixed Cost | B16: =B8+B9+B10+B11 -> 180000
A17: Estimated monthly profit | B17: =B15-B16 -> 540000
A18: Theoritical Max Monthly Revenue | B18: =TIME_ENGINE!B37*TIME_ENGINE!B36 -> 1248000
A19: Total Monthly Costs | B19: =SUM(B9:B11)+B8 -> 180000
A20: Revenue per client | B20: =SCENARIO_LAB!B11 -> 12000

Sheet TIME_ENGINE
A1: TOTAL MONTHLY REVENUE | B1: ='INPUTS '!B3*'INPUTS '!B4 -> 720000
A2: Revenue per available hour (RevPAH) | B2: =B1/B36 -> 3461.5385
A3: Highest Utilization across all hours | B3: =MAX(F20:F28) -> 1.3333333
A4: Average Utilixation (%) | B4: =AVERAGE(F20:F28) -> 0.79166667
A5: Peak Frequency | B5: =COUNTIF(F20:F28,">0.8") -> 3
A6: Demand Concentration | B6: =(B34+B35)/D29 -> 0.425
A7: Overload events | B7: =E29 -> 3
A8: Revenue Realization (%) | B8: ='INPUTS '!B15/'INPUTS '!B18 -> 0.57692308
A9: Estimated monthly Profit | B9: =B1-'INPUTS '!B19 -> 540000
A10: Break-even client | B10: =ROUNDUP('INPUTS '!B19/'INPUTS '!B4,0) -> 15
A11: Profit margin | B11: ='INPUTS '!B17/'INPUTS '!B15 -> 0.75
A12: Client Capacity | B12: =B38/16 -> 78
A13: Capacity pressure(%) | B13: ='INPUTS '!B3/TIME_ENGINE!B12 -> 0.76923077
A14: Client Headroom | B14: =B12-'INPUTS '!B3 -> 18
A15: Revenue Available | B15: =B14*'INPUTS '!B20 -> 216000
A17: SELLABLE HOUR MODEL
A19: Hour Block | B19: Trainers available | C19: Capacity | D19: Clients Arrived | E19: Overload | F19: Utilization | G19: Status | H19: Revenue | I19: Surge Triggered
A20: 6-7 am | B20: 2 | C20: =B20*2 -> 4 | D20: 3 | E20: =IF(D20>C20,1,0) -> 0 | F20: =D20/C20 -> 0.75 | G20: =IF(F20>0.75,"Peak", IF(F20>0.4, "Healthy", "Underused")) -> Healthy | H20: =D20*TIME_ENGINE!B21 -> 12 | I20: =IF(B20>3, "YES", "NO") -> NO
A21: 7-8 am | B21: 4 | C21: =B21*2 -> 8 | D21: 9 | E21: =IF(D21>C21,1,0) -> 1 | F21: =D21/C21 -> 1.125 | G21: =IF(F21>0.75,"Peak", IF(F21>0.4, "Healthy", "Underused")) -> Peak | H21: =D21*TIME_ENGINE!B22 -> 27 | I21: =IF(B21>3, "YES", "NO") -> YES
A22: 8-9 am | B22: 3 | C22: =B22*2 -> 6 | D22: 8 | E22: =IF(D22>C22,1,0) -> 1 | F22: =D22/C22 -> 1.3333333 | G22: =IF(F22>0.75,"Peak", IF(F22>0.4, "Healthy", "Underused")) -> Peak | H22: =D22*TIME_ENGINE!B23 -> 24 | I22: =IF(B22>3, "YES", "NO") -> NO
A23: 9-10 am | B23: 3 | C23: =B23*2 -> 6 | D23: 7 | E23: =IF(D23>C23,1,0) -> 1 | F23: =D23/C23 -> 1.1666667 | G23: =IF(F23>0.75,"Peak", IF(F23>0.4, "Healthy", "Underused")) -> Peak | H23: =D23*TIME_ENGINE!B24 -> 0 | I23: =IF(B23>3, "YES", "NO") -> NO
A25: 5-6 pm | B25: 3 | C25: =B25*2 -> 6 | D25: 2 | E25: =IF(D25>C25,1,0) -> 0 | F25: =D25/C25 -> 0.33333333 | G25: =IF(F25>0.75,"Peak", IF(F25>0.4, "Healthy", "Underused")) -> Underused | H25: =D25*TIME_ENGINE!B26 -> 6 | I25: =IF(B25>3, "YES", "NO") -> NO
A26: 6-7 pm | B26: 3 | C26: =B26*2 -> 6 | D26: 2 | E26: =IF(D26>C26,1,0) -> 0 | F26: =D26/C26 -> 0.33333333 | G26: =IF(F26>0.75,"Peak", IF(F26>0.4, "Healthy", "Underused")) -> Underused | H26: =D26*TIME_ENGINE!B27 -> 8 | I26: =IF(B26>3, "YES", "NO") -> NO
A27: 7-8 pm | B27: 4 | C27: =B27*2 -> 8 | D27: 5 | E27: =IF(D27>C27,1,0) -> 0 | F27: =D27/C27 -> 0.625 | G27: =IF(F27>0.75,"Peak", IF(F27>0.4, "Healthy", "Underused")) -> Healthy | H27: =D27*TIME_ENGINE!B28 -> 15 | I27: =IF(B27>3, "YES", "NO") -> YES
A28: 8-9 pm | B28: 3 | C28: =B28*2 -> 6 | D28: 4 | E28: =IF(D28>C28,1,0) -> 0 | F28: =D28/C28 -> 0.66666667 | G28: =IF(F28>0.75,"Peak", IF(F28>0.4, "Healthy", "Underused")) -> Healthy | H28: =D28*TIME_ENGINE!B29 -> 0 | I28: =IF(B28>3, "YES", "NO") -> NO
A29: TOTAL | D29: =SUM(D20:D28) -> 40 | E29: =SUM(E20:E28) -> 3
A33: CALCULATIONS | D33: Hour Block | E33: LOW | F33: MEDIUM | G33: HIGH
A34: Largest (clients arrived) | B34: =LARGE(D20:D28,1) -> 9 | D34: 6-7 am | E34: =IF(F20<0.5,F20,NA()) -> #N/A | F34: =IF(AND(F20>0.5,F20<0.75),F20,NA()) -> #N/A | G34: =IF(F20>=0.75,F20,NA()) -> 0.75
A35: Second largest (clent arrived) | B35: =LARGE(D20:D28,2) -> 8 | D35: 7-8 am | E35: =IF(F21<0.5,F21,NA()) -> #N/A | F35: =IF(AND(F21>0.5,F21<0.75),F21,NA()) -> #N/A | G35: =IF(F21>=0.75,F21,NA()) -> 1.125
A36: Monthly Available Hours | B36: =8*26 -> 208 | D36: 8-9 am | E36: =IF(F22<0.5,F22,NA()) -> #N/A | F36: =IF(AND(F22>0.5,F22<0.75),F22,NA()) -> #N/A | G36: =IF(F22>=0.75,F22,NA()) -> 1.3333333
A37: Max revenue per hour | B37: =8*'INPUTS '!B5 -> 6000 | D37: 9-10 am | E37: =IF(F23<0.5,F23,NA()) -> #N/A | F37: =IF(AND(F23>0.5,F23<0.75),F23,NA()) -> #N/A | G37: =IF(F23>=0.75,F23,NA()) -> 1.1666667
A38: Total Monthly Session capacity | B38: =48*26 -> 1248 | F38: =IF(AND(F24>0.5,F24<0.75),F24,NA()) -> #N/A | G38: =IF(F24>=0.75,F24,NA()) -> #N/A
D39: 5-6 pm | E39: =IF(F25<0.5,F25,NA()) -> 0.33333333 | F39: =IF(AND(F25>0.5,F25<0.75),F25,NA()) -> #N/A | G39: =IF(F25>=0.75,F25,NA()) -> #N/A
D40: 6-7 pm | E40: =IF(F26<0.5,F26,NA()) -> 0.33333333 | F40: =IF(AND(F26>0.5,F26<0.75),F26,NA()) -> #N/A | G40: =IF(F26>=0.75,F26,NA()) -> #N/A
D41: 7-8 pm | E41: =IF(F27<0.5,F27,NA()) -> #N/A | F41: =IF(AND(F27>0.5,F27<0.75),F27,NA()) -> 0.625 | G41: =IF(F27>=0.75,F27,NA()) -> #N/A
D42: 8-9 pm | E42: =IF(F28<0.5,F28,NA()) -> #N/A | F42: =IF(AND(F28>0.5,F28<0.75),F28,NA()) -> 0.66666667 | G42: =IF(F28>=0.75,F28,NA()) -> #N/A
A49: NOTES:
A50: 1. Utilization >100% indicates overload demand.
A51: 2. The revenue realization shows that the gym is operating at 58%.
A52: 3.The session capacit is obtained by:
...

Sheet DASHBOARD
B1: STUDIO PERFORMANCE DASHBOARD
B5: ACTIVE CLIENTS | C5: MONTHLY REVENUE | D5: REVENUE PER HOUR | E5: AVERAGE UTILIZATION | F5: OVERLOAD EVENTS (WEEK) | G5: CAPACITY UTILIZATION VALUE | H5: REVENUE REALIZATION
B6: ='INPUTS '!B3 -> 60 | C6: ='INPUTS '!B15 -> 720000 | D6: =TIME_ENGINE!B2 -> 3461.5385 | E6: =TIME_ENGINE!B4 -> 0.79166667 | F6: =TIME_ENGINE!B7 -> 3 | G6: =D6/TIME_ENGINE!B37 -> 0.57692308 | H6: =TIME_ENGINE!B8 -> 0.57692308
B8: MONTHLY PROFIT | C8: PROFIT PER HOUR | D8: BREAK-EVEN CLIENT COUNT | E8: PROFIT MARGIN | F8: CAPACITY PRESSURE
B9: =TIME_ENGINE!B9 -> 540000 | C9: =B9/TIME_ENGINE!B36 -> 2596.1538 | D9: =TIME_ENGINE!B10 -> 15 | E9: =TIME_ENGINE!B11 -> 0.75 | F9: =TIME_ENGINE!B13 -> 0.76923077 | G9: OPERATIONAL STATUS: | H9: =IF(SCENARIO_LAB!F13<0.7,"Comfortable", IF(SCENARIO_LAB!F13<0.82, "Healthy", IF(SCENARIO_LAB!F13<0.9, "Rising Pressure", IF(SCENARIO_LAB!F13<0.95, "Hire Soon", "Capacity Risk")))) -> Healthy
B11: REVENUE AVAILABlLE
B12: =TIME_ENGINE!B15 -> 216000 | G12: ACTION RECOMMENDED | H12: =IF(SCENARIO_LAB!F13<0.7,"Focus on filling Capacity", IF(SCENARIO_LAB!F13<0.82, "Optimize scheduling", IF(SCENARIO_LAB!F13<0.9, "Test Price Adjustments", IF(SCENARIO_LAB!F13<0.95, "Prepare hiring plan", "Hire immediately")))) -> Optimize scheduling
